output/merchant-free.tsv
id	title	description	availability	inventory	condition	price	sale_price	link	image_link	brand	item_group_id	product_type	google_product_category
114154157311	Нут, турецкий горох - 1кг	Нут, турецкий горох, Индия	in stock	999	new	115.00 UAH		https://smartfood.org.ua/nuts/tproduct/320926945-107777128241-nut-turetskii-goroh?editionuid=114154157311	https://static.tildacdn.com/tild3334-6632-4438-b261-333262653561/66d0a523af5890003bb6.jpg	smartfood.org.ua	107777128241	Орехи	433
778465479011	Нут, турецкий горох - 500г	Нут, турецкий горох, Индия	in stock	999	new	69.00 UAH		https://smartfood.org.ua/nuts/tproduct/320926945-107777128241-nut-turetskii-goroh?editionuid=778465479011	https://static.tildacdn.com/tild3334-6632-4438-b261-333262653561/66d0a523af5890003bb6.jpg	smartfood.org.ua	107777128241	Орехи	433
830316253041	Лен коричневый - 500г	Семена льна коричневые	in stock	999	new	52.00 UAH		https://smartfood.org.ua/seeds/tproduct/320930816-590878034961-len-korichnevii?editionuid=830316253041	https://static.tildacdn.com/tild3164-3463-4862-b034-386537653864/NDhVH6OhAAi7a6IpVqAw.jpg	smartfood.org.ua	590878034961	Семена, семечки	433
314569625571	Лен коричневый - 1кг	Семена льна коричневые	in stock	999	new	90.00 UAH		https://smartfood.org.ua/seeds/tproduct/320930816-590878034961-len-korichnevii?editionuid=314569625571	https://static.tildacdn.com/tild3164-3463-4862-b034-386537653864/NDhVH6OhAAi7a6IpVqAw.jpg	smartfood.org.ua	590878034961	Семена, семечки	433
787800090731	Арахис сырой - 500г	Арахис сырой высшего сорта, Узбекистан	in stock	999	new	98.00 UAH		https://smartfood.org.ua/nuts/tproduct/320926945-473562956981-arahis-siroi?editionuid=787800090731	https://static.tildacdn.com/tild3139-3232-4261-b139-623166333933/large_D0B0D180D0B0D1.jpg	smartfood.org.ua	473562956981	Орехи	433
307797719391	Кедровый орех очищенный - 500г	Ядра кедровых орехов, очищенные	in stock	999	new	879.00 UAH		https://smartfood.org.ua/nuts/tproduct/320926945-603659820731-kedrovii-oreh-ochischennii?editionuid=307797719391	https://static.tildacdn.com/tild6135-6637-4335-a333-336333636263/yadro_kedra-500x500.jpg	smartfood.org.ua	603659820731	Орехи	433
317305176871	Кедровый орех очищенный - 1кг	Ядра кедровых орехов, очищенные	in stock	999	new	1,849.00 UAH		https://smartfood.org.ua/nuts/tproduct/320926945-603659820731-kedrovii-oreh-ochischennii?editionuid=317305176871	https://static.tildacdn.com/tild6135-6637-4335-a333-336333636263/yadro_kedra-500x500.jpg	smartfood.org.ua	603659820731	Орехи	433
956214582201	Арахис соленый - 500г	Арахис соленый очищенный высшего сорта	in stock	999	new	94.00 UAH		https://smartfood.org.ua/nuts/tproduct/320926945-184798587541-arahis-solenii?editionuid=956214582201	https://static.tildacdn.com/tild3962-6331-4833-a135-623065363231/82927797a8596d6a504e.jpeg	smartfood.org.ua	184798587541	Орехи	433
738118203071	"Шоколад черный ""Studentska"" с изюмом и арахисом 180г"	Шоколад черный Studentska с изюмом и арахисом 180г	in stock	999	new	79.00 UAH		https://smartfood.org.ua/chocolate-sweets/tproduct/320927101-738118203071-shokolad-chernii-studentska-s-izyumom-i	https://static.tildacdn.com/tild3238-3865-4439-a232-633837653966/2687481147_w640_h640.jpg	Orion	738118203071	Шоколад и Сладости	4748
291787120941	"Шоколад молочный ""Studentska pecet"" с кокосом и арахисом 180г"	"Шоколад молочный ""Studentska pecet"" с кокосом и арахисом 180г"	in stock	999	new	79.00 UAH		https://smartfood.org.ua/chocolate-sweets/tproduct/320927101-291787120941-shokolad-molochnii-studentska-pecet-s-ko	https://static.tildacdn.com/tild3735-6163-4861-b832-323631666337/2008215740_shokolad-.jpg	Orion	291787120941	Шоколад и Сладости	4748
554174736931	"Шоколад молочный ""Studentska pecet"" с вишней и арахисом 180г"	"Шоколад молочный ""Studentska pecet"" с вишней и арахисом 180г"	in stock	999	new	79.00 UAH		https://smartfood.org.ua/chocolate-sweets/tproduct/320927101-554174736931-shokolad-molochnii-studentska-pecet-s-vi	https://static.tildacdn.com/tild3864-3565-4265-b332-323136363231/2008214176_shokolad-.jpg	Orion	554174736931	Шоколад и Сладости	4748
501221745311	"Шоколад молочный ""Studentska pecet"" с малиной, арахисом и мармеладом 180г"	Шоколад молочный Studentska pecet с малиной, арахисом и мармеладом 180г	in stock	999	new	79.00 UAH		https://smartfood.org.ua/chocolate-sweets/tproduct/320927101-501221745311-shokolad-molochnii-studentska-pecet-s-ma	https://static.tildacdn.com/tild3764-3232-4830-b735-306330393832/2016122573_w640_h640.jpg	Orion	501221745311	Шоколад и Сладости	4748
473026140191	"Шоколад молочный ""Studentska"" с гушей и арахисом 180г"	"Шоколад молочный ""Studentska"" с гушей и арахисом Чехия 180г"	in stock	999	new	79.00 UAH		https://smartfood.org.ua/chocolate-sweets/tproduct/320927101-473026140191-shokolad-molochnii-studentska-s-gushei-i	https://static.tildacdn.com/tild6561-6566-4431-b838-313435333634/1139889912_shokolad-.jpg	Orion	473026140191	Шоколад и Сладости	4748
625686013981	"Шоколад бело-молочный ""Studentska"" c арахисом и изюмом 180г"	Шоколад бело-молочный Studentska c арахисом и изюмом 180г	in stock	999	new	79.00 UAH		https://smartfood.org.ua/chocolate-sweets/tproduct/320927101-625686013981-shokolad-belo-molochnii-studentska-c-ara	https://static.tildacdn.com/tild3536-3862-4262-b063-613461333638/ddd484a34bbe81724356.jpg	Orion	625686013981	Шоколад и Сладости	4748
785312552861	"Шоколад белый ""Studentska"" c арахисом и изюмом 180г"	Шоколад белый Studentska c арахисом и изюмом 180г	in stock	999	new	79.00 UAH		https://smartfood.org.ua/chocolate-sweets/tproduct/320927101-785312552861-shokolad-belii-studentska-c-arahisom-i-i	https://static.tildacdn.com/tild6362-6638-4761-a466-633837366138/Czekolada-studentska.jpg	Orion	785312552861	Шоколад и Сладости	4748
923268321171	Шоколад Milka Oreo (с печеньем) 300г	Шоколад Milka Oreo (с печеньем) Швейцария 300г	in stock	999	new	146.00 UAH		https://smartfood.org.ua/chocolate-sweets/tproduct/320927101-923268321171-shokolad-milka-oreo-s-pechenem-300g	https://static.tildacdn.com/stor3039-3265-4766-b136-393238656334/89716373.jpg	Milka	923268321171	Шоколад и Сладости	4748
294097388861	Макаронные изделия Farfalle Barilla (Бабочки) 500г	Макаронные изделия Farfalle Barilla (Бабочки) 500г	in stock	999	new	76.00 UAH		https://smartfood.org.ua/pasta/tproduct/320928224-294097388861-makaronnie-izdeliya-farfalle-barilla-bab	https://static.tildacdn.com/tild6531-3533-4236-b662-353331613137/040820201596561101SN.jpg	Barilla	294097388861	Макаронные изделия	434
470332237561	Макароны детские из органической муки Ditalini Costa 200г	Макароны детские из органической муки Ditalini Costa, 200г	in stock	999	new	97.00 UAH		https://smartfood.org.ua/pasta/tproduct/320928224-470332237561-makaroni-detskie-iz-organicheskoi-muki-d	https://static.tildacdn.com/tild3730-6161-4863-b561-346234303939/2539362646_w700_h500.jpg	smartfood.org.ua	470332237561	Макаронные изделия	434
520816406741	Макаронные изделия Penne Rirgate TRE MULINI 1кг	Макароны Penne Rirgate TRE MULINI 1кг. из Италии.	in stock	999	new	87.00 UAH		https://smartfood.org.ua/pasta/tproduct/320928224-520816406741-makaronnie-izdeliya-penne-rirgate-tre-mu	https://static.tildacdn.com/tild3035-3439-4466-b235-353032646330/253403361_images_201.jpg	Tre Mulini	520816406741	Макаронные изделия	434
751888664101	Макаронные изделия Pipe Rigate Barilla (рожки) 500г	Макаронные изделия Pipe Rigate Barilla (рожки) N91 500г	in stock	999	new	76.00 UAH		https://smartfood.org.ua/pasta/tproduct/320928224-751888664101-makaronnie-izdeliya-pipe-rigate-barilla	https://static.tildacdn.com/tild3939-6232-4961-b662-316137656564/92371593378849.jpg	Barilla	751888664101	Макаронные изделия	434
564791887221	Макароны яичные Macaron DOBRUSIA 250г	Макаронные изделия Macaron DOBRUSIA Польша 250г	in stock	999	new	41.00 UAH		https://smartfood.org.ua/pasta/tproduct/320928224-564791887221-makaroni-yaichnie-macaron-dobrusia-250g	https://static.tildacdn.com/tild3737-3562-4334-a436-666334303235/253403526_images_201.jpg	smartfood.org.ua	564791887221	Макаронные изделия	434
825501897651	Макаронные изделия Farfalline Barilla № 59 500г	Макароны Farfalline Barilla № 59 (мини-Бабочки ) 500г	in stock	999	new	76.00 UAH		https://smartfood.org.ua/pasta/tproduct/320928224-825501897651-makaronnie-izdeliya-farfalline-barilla-5	https://static.tildacdn.com/tild6430-3637-4537-b436-396465366631/74353583340366159465.jpg	Barilla	825501897651	Макаронные изделия	434
